Workbook

Sheet Cómo usar
A1: Cierre del plan estratégico CINDE 2022-2026 · Datos del tablero
A3: Este archivo es la fuente del tablero. Para actualizarlo, edite las hojas y envíe el archivo para cargarlo de nuevo.
A4: Metas: una fila por meta del plan. Edite las columnas Logrado, Pendiente y Porcentaje (número de 0 a 100, sin el signo %).
A5: Acciones: una fila por acción. Edite Estado (En curso, Rezagado, Mixto o Cumplido), Estado detalle, Logrado y Pendiente.
A6: Programas: una fila por programa. Edite Estado, Logrado y Pendiente.
A7: Las columnas en gris (% final) son fórmulas: el % de la acción es el promedio de sus metas, y el % del programa es el promedio de sus acciones del plan (sin las filas fuera del plan). No las edite.
A8: Tipo de meta: Priorizada, No priorizada o Fuera del plan. Fuera del plan = 'Sí' excluye la acción del promedio del programa.
A9: Para agregar una meta, copie una fila en Metas y use un meta_id nuevo con el accion_id de su acción (ej.: P4-A1-M5).
A10: Los datos marcados con * provienen del plan de mejoramiento Minciencias o del informe de gestión y no fueron verificados.
A12: Hojas Gráficas y Análisis: se calculan solas a partir de Programas, Acciones y Metas. No las edite. La página web no las lee, así que no afectan el tablero.
A13: Hoja Minciencias y columna categoria_minciencias (hoja Metas): ubican cada meta en una categoría del formato de autoevaluación de Minciencias. Para cambiar la ubicación de una meta, elija otra categoría en esa columna. La página web usa estos datos en la pestaña "Informe para reconocimiento de CINDE como centro de investigación".
A14: Las categorías de la hoja Minciencias se tomaron del formato m601pr05g04f01 (informe de autoevaluación para el reconocimiento de centros de investigación). El criterio 4.1 se divide en las tres tipologías de producto: nuevo conocimiento, apropiación social y formación de investigadores.
... A16: Hoja Preguntas_formato: todas las preguntas del formato de Minciencias por criterio, con la respuesta (Sí, No o Sin evidencia) según las evidencias del plan estratégico. Cuando un área responda una pregunta, escriba la respuesta en la columna amarilla respuesta_area y, si corresponde, cambie la columna respuesta.

Sheet Gráficas
A1: Cierre del plan estratégico CINDE 2022-2026
A2: Las gráficas se actualizan solas con los datos de la hoja Metas. Falta el P7 (Finanzas e infraestructura).
A4: Avance del plan | C4: Acciones del plan | E4: Cumplidas | G4: En curso | I4: Rezagadas | K4: Mixtas
A5: =Análisis!B12 -> 0.58 | C5: =Análisis!D12 -> 29 | E5: =Análisis!E12 -> 0 | G5: =Análisis!F12 -> 17 | I5: =Análisis!G12 -> 6 | K5: =Análisis!H12 -> 6
A7: Lectura
A8: ="El plan llega a "&TEXT(Análisis!B12,"0%")&" de avance, con "&Análisis!E12&" de "&Análisis!D12&" acciones cumplidas." -> El plan llega a 58% de avance, con 0 de 29 acciones cumplidas.
A9: ="El programa con mayor avance es "&Análisis!B16&" ("&TEXT(Análisis!C16,"0%")&") y el de menor avance, "&Análisis!B21&" ("&TEXT(Análisis!C21,"0%")&")." -> El programa con mayor avance es P2 Formación (79%) y el de menor avance, P5 Planeación y CEA (46%).
A10: ="De "&Análisis!F31&" metas del plan, "&Análisis!B31&" están logradas (90% o más) y "&Análisis!E31&" tienen avance bajo (menos de 40%)." -> De 98 metas del plan, 17 están logradas (90% o más) y 27 tienen avance bajo (menos de 40%).
A11: ="Las metas priorizadas en 2025-2026 promedian "&TEXT(Análisis!B41,"0%")&"; las no priorizadas, "&TEXT(Análisis!C41,"0%")&"." -> Las metas priorizadas en 2025-2026 promedian 63%; las no priorizadas, 38%.

Sheet Programas
A1: programa_id | B1: programa | C1: estado | D1: logrado | E1: pendiente | F1: % final
A2: P1 | B2: P1 Investigación-desarrollo | C2: En curso | D2: Grupos categorizados; proyectos del SGR destacados; producción continua | E2: Medición por investigador; oferta propia sin financiar; nuevas generaciones | F2: =ROUND(AVERAGEIFS(Acciones!$I:$I,Acciones!$B:$B,A2,Acciones!$F:$F,"No"),0) -> 57
A3: P2 | B3: P2 Formación | C3: En curso | D3: Acreditaciones, registros y cohortes por convenios | E3: Nuevos programas sin cohorte; Maestría en Primera Infancia | F3: =ROUND(AVERAGEIFS(Acciones!$I:$I,Acciones!$B:$B,A3,Acciones!$F:$F,"No"),0) -> 79
A4: P3 | B4: P3 Circulación del conocimiento | C4: En curso | D4: Revistas, producción editorial, redes y eventos internacionales | E4: Documentos sin aprobar; feria propia; convenios de circulación; mediciones | F4: =ROUND(AVERAGEIFS(Acciones!$I:$I,Acciones!$B:$B,A4,Acciones!$F:$F,"No"),0) -> 49
A5: P4 | B5: P4 Transformación digital | C5: En curso | D5: Sistemas, infraestructura y soporte | E5: Escuela Digital: plataforma, modelo pedagógico, metodologías y cursos internacionales | F5: =ROUND(AVERAGEIFS(Acciones!$I:$I,Acciones!$B:$B,A5,Acciones!$F:$F,"No"),0) -> 50
A6: P5 | B6: P5 Planeación y CEA | C6: En curso | D6: Reconocimiento ante Minciencias; gestión de recursos; nueva estructura | E6: Documentos sin aprobar; ningún CEA nuevo; ingresos lejos de la meta | F6: =ROUND(AVERAGEIFS(Acciones!$I:$I,Acciones!$B:$B,A6,Acciones!$F:$F,"No"),0) -> 46
A7: P6 | B7: P6 Talento humano | C7: En curso | D7: Nivelación salarial, SG-SST y talleres | E7: Políticas formales y mediciones de clima y percepción | F7: =ROUND(AVERAGEIFS(Acciones!$I:$I,Acciones!$B:$B,A7,Acciones!$F:$F,"No"),0) -> 68

Sheet Acciones
A1: accion_id | B1: programa_id | C1: accion | D1: estado | E1: estado_detalle | F1: fuera_del_plan | G1: logrado | H1: pendiente | I1: % final
A2: P1-A1 | B2: P1 | C2: A1 Grupos y líneas de investigación | D2: En curso | E2: En curso (priorizada 80%) / Rezagado (no priorizada 50%) | F2: No | G2: 3 de 4 grupos en A1 o A; 6 líneas articuladas; 50 productos de apropiación (2026); más de 5.900 actores (2024) | H2: Grupo de Desarrollo Rural en C; medición por investigador; publicar la sistematización | I2: =ROUND(AVERAGEIF(Metas!$C:$C,A2,Metas!$H:$H),0) -> 75
A3: P1-A2 | B3: P1 | C3: A2 Co-creación de programas y proyectos | D3: Mixto | E3: En curso (priorizada 75%) / Rezagado (no priorizada 30%) | F3: No | G3: Primer lugar en desempeño del SGR; más de 5 proyectos y el programa Territorios del Buen Vivir; colaboratorio; Ékora | H3: Seguimiento a todos los proyectos; encuentros semestrales; financiar la oferta propia; Ékora suspendida | I3: =ROUND(AVERAGEIF(Metas!$C:$C,A3,Metas!$H:$H),0) -> 57
A4: P1-A3 | B4: P1 | C4: A3 Semilleros y jóvenes investigadores | D4: Rezagado | E4: Rezagado (priorizada 30%, no priorizada 60%) | F4: No | G4: 5 jóvenes investigadores (2022); 2 practicantes y convenio con la UdeA (2025); lineamiento de semilleros | H4: Datos de 2023 a 2026; conteo de semilleros; diplomado sin participantes | I4: =ROUND(AVERAGEIF(Metas!$C:$C,A4,Metas!$H:$H),0) -> 38
A5: P2-A1 | B5: P2 | C5: A1 Nueva oferta de formación avanzada y continua | D5: En curso | E5: En curso | F5: No | G5: Registro del Doctorado en Educación (2026)*; documento maestro de la Maestría en Paz; MEDH Sabaneta renovada; especializaciones con CLACSO | H5: Cohortes de los nuevos programas; MEDH Manizales; 4 programas de formación continua al año | I5: =ROUND(AVERAGEIF(Metas!$C:$C,A5,Metas!$H:$H),0) -> 74
A6: P2-A2 | B6: P2 | C6: A2 Aseguramiento de la calidad | D6: Mixto | E6: En curso (priorizada 77%) / Rezagado (no priorizada 10%) | F6: No | G6: Acreditación de la MDES por 6 años (2023); reacreditación del doctorado*; transformaciones del doctorado implementadas | H6: Acreditación MEDH Sabaneta; renovación MEDH Manizales; Maestría en Primera Infancia | I6: =ROUND(AVERAGEIF(Metas!$C:$C,A6,Metas!$H:$H),0) -> 79
A7: P2-A3 | B7: P2 | C7: A3 Sostenibilidad de los programas | D7: En curso | E7: En curso | F7: No | G7: Convenios que generaron cohortes; 3 de 4 programas en punto de equilibrio; plan de marketing; incentivos al 90% | H7: Maestría en Primera Infancia; equilibrio en todos los programas; aprobar incentivos | I7: =ROUND(AVERAGEIF(Metas!$C:$C,A7,Metas!$H:$H),0) -> 83
A8: P3-A1 | B8: P3 | C8: A1 Comunicación estratégica | D8: En curso | E8: En curso | F8: No | G8: Plan integral de comunicación al 85%; alianzas con Alliance CPHA y la U. Luis Amigó; planes de mercadeo 2025 y 2026 | H8: Aprobar el manual; alianzas con medios; formato continuo; espacio con egresados | I8: =ROUND(AVERAGEIF(Metas!$C:$C,A8,Metas!$H:$H),0) -> 51
A9: P3-A2 | B9: P3 | C9: A2 Comunicación para el desarrollo | D9: En curso | E9: En curso | F9: No | G9: Productos con actores casi todos los años; participación en ferias externas | H9: Feria propia de I+D; plan de periodismo científico | I9: =ROUND(AVERAGEIF(Metas!$C:$C,A9,Metas!$H:$H),0) -> 42
A10: P3-A3 | B10: P3 | C10: A3 Línea editorial | D10: En curso | E10: En curso | F10: No | G10: RLCSNJ en CAPES A2 y Aletheia en B; 19 libros y cartillas (2026); coediciones con CLACSO y UMZ | H10: Política editorial; plan anual formal; coedición anual; catálogo; egresados | I10: =ROUND(AVERAGEIF(Metas!$C:$C,A10,Metas!$H:$H),0) -> 59
A11: P3-A4 | B11: P3 | C11: A4 Redes, eventos y movilidades | D11: Mixto | E11: En curso (priorizada 45%) / Rezagado (no priorizada 25%) | F11: No | G11: 27 redes (2022) y 29 (2025); eventos anuales con aliados; incidencia en NiñezYA y Alianza por la Niñez | H11: Medir el incremento; redes en Europa y Norteamérica; protocolos; convenio de circulación | I11: =ROUND(AVERAGEIF(Metas!$C:$C,A11,Metas!$H:$H),0) -> 42
A12: P3-N | B12: P3 | C12: P3-N Metas editoriales nuevas | D12: Rezagado | E12: Rezagado | F12: Sí | G12: Vinculación a MBIES y al Comité de Editoriales Universitarias de Antioquia | H12: Publicación con lenguajes diversos; soporte de capacitaciones | I12: =ROUND(AVERAGEIF(Metas!$C:$C,A12,Metas!$H:$H),0) -> 73
A13: P4-A1 | B13: P4 | C13: A1 Transformación digital | D13: En curso | E13: En curso | F13: No | G13: SII con módulos de I+D, formación, certificaciones, proveedores y laboral; mapeo de convocatorias | H13: Costeo de proyectos; documentación; plan de formación | I13: =ROUND(AVERAGEIF(Metas!$C:$C,A13,Metas!$H:$H),0) -> 78
... A34: P6-N | B34: P6 | C34: P6-N Nómina y afiliaciones | D34: En curso | E34: En curso | F34: Sí | G34: 100% en el Q1; migración a Siesa SBS | H34: Reporte del Q2 y el Q3 | I34: =ROUND(AVERAGEIF(Metas!$C:$C,A34,Metas!$H:$H),0) -> 90

Sheet Metas
A1: meta_id | B1: programa_id | C1: accion_id | D1: tipo | E1: meta | F1: logrado | G1: pendiente | H1: porcentaje | I1: categoria_minciencias
A2: P1-A1-M1 | B2: P1 | C2: P1-A1 | D2: Priorizada | E2: 75% de grupos en los más altos estándares | F2: 3 de 4 grupos en A1 o A (2022 y 2025) | G2: El grupo de Desarrollo Rural sigue en C | H2: 100 | I2: 4.1-NC
A3: P1-A1-M2 | B3: P1 | C3: P1-A1 | D3: Priorizada | E3: 80% de líneas operando y articuladas con la formación | F3: 7 líneas activas articuladas entre maestría y doctorado; plan de líneas 2025-2030 | G3: Confirmar que son el total de líneas | H3: 90 | I3: 4.1-NC
A4: P1-A1-M3 | B4: P1 | C4: P1-A1 | D4: No priorizada | E4: 1 sistematización de transformaciones en líneas y grupos | F4: Capítulos de impactos y libro Devenires en edición (2022); 2 productos de análisis (2025) | G4: Publicar el libro y cerrar la sistematización | H4: 50 | I4: 4.1-NC
A5: P1-A1-M4 | B5: P1 | C5: P1-A1 | D5: Priorizada | E5: 1 producto de nuevo conocimiento al año por investigador y proyecto | F5: Publicaciones indexadas (2023); 6 publicaciones (2025) | G5: No se mide por investigador; registro de productos al 22% (2026) | H5: 50 | I5: 4.1-NC
A6: P1-A1-M5 | B6: P1 | C6: P1-A1 | D6: Priorizada | E6: 1 producto de apropiación social al año por investigador y proyecto | F6: 6 productos (2025); 50 productos en la matriz 2026 | G6: No se mide por investigador; 40% frente a una meta de 50% (2026) | H6: 60 | I6: 4.1-ASC
A7: P1-A1-M6 | B7: P1 | C7: P1-A1 | D7: Priorizada | E7: Capacidad instalada en 2.500 actores sociales | F7: Más de 5.900 participantes en proyectos de regalías (2024) | G7: Ninguno | H7: 100 | I7: 4.1-ASC
A8: P1-A2-M1 | B8: P1 | C8: P1-A2 | D8: Priorizada | E8: 90% de metas técnicas y presupuestales con seguimiento semestral | F8: 100 puntos en GESPROY y primer lugar del SGR (2023); máxima calificación (2024); seguimiento a 8 proyectos (2025) | G8: Seguimiento a los proyectos que no son del SGR | H8: 75 | I8: 4.1-NC
A9: P1-A2-M2 | B9: P1 | C9: P1-A2 | D9: Priorizada | E9: Colaboratorio con encuentro semestral | F9: Encuentro nacional con 4 macroproyectos co-diseñados (2022); colaboratorio (2025) | G9: Encuentros semestrales todos los años | H9: 60 | I9: 4.1-NC
A10: P1-A2-M3 | B10: P1 | C10: P1-A2 | D10: Priorizada | E10: 1 programa nuevo y 5 proyectos | F10: Programa Territorios del Buen Vivir; más de 5 proyectos nuevos | G10: Financiar las propuestas de oferta propia de 2026 (35%) | H10: 90 | I10: 4.1-NC
A11: P1-A2-M4 | B11: P1 | C11: P1-A2 | D11: No priorizada | E11: 100% del equipo de I+D vinculado a programas y proyectos | F11: Sin evidencia | G11: Medir la vinculación | H11: 0 | I11: 3.1
A12: P1-A2-M5 | B12: P1 | C12: P1-A2 | D12: No priorizada | E12: 1 escuela digital intercampos | F12: Ékora lanzada en 2024 | G12: Suspendida desde 2025 (ver P4-A3) | H12: 60 | I12: 3.3
A13: P1-A3-M1 | B13: P1 | C13: P1-A3 | D13: Priorizada | E13: 10 practicantes o pasantes (2 al año) | F13: 2 practicantes y convenio con la UdeA (2025) | G13: Datos de 2022 a 2024 y de 2026 | H13: 30 | I13: 4.1-FRH
... A94: P6-A1-M1 | B94: P6 | C94: P6-A1 | D94: Priorizada | E94: 1 taller nacional al año | F94: Encuentros nacionales en 2022 | G94: Sin taller nacional 2023 al 2026 | H94: 20 | I94: 3.1
A95: P6-A1-M2 | B95: P6 | C95: P6-A1 | D95: Priorizada | E95: 2 talleres de indagación apreciativa al año | F95: 10 talleres (2022-2026) | H95: 100 | I95: 3.1
A96: P6-A1-M3 | B96: P6 | C96: P6-A1 | D96: Priorizada | E96: Política de reconocimiento e incentivos | F96: Documentos de beneficios 100% (2025) | G96: Socializarlo | H96: 95 | I96: 3.1
A97: P6-A2-M1 | B97: P6 | C97: P6-A2 | D97: Priorizada | E97: Comités de Convivencia y COPASST consolidados | F97: Elegidos en 2025 y en funcionamiento | H97: 100 | I97: 3.1
A98: P6-A2-M2 | B98: P6 | C98: P6-A2 | D98: Priorizada | E98: Capacitación pertinente a los comités | F98: Capacitaciones generales con la ARL | G98: Capacitación específica a los comités | H98: 80 | I98: 3.1
A99: P6-A2-M3 | B99: P6 | C99: P6-A2 | D99: Priorizada | E99: Cronograma de actividades del SG-SST | F99: Plan anual con la ARL en 2025 y 2026 | G99: Cerrar el plan 2026 | H99: 90 | I99: 3.1
A100: P6-A2-M4 | B100: P6 | C100: P6-A2 | D100: Priorizada | E100: Documentación y seguimiento del SG-SST | F100: Estándares mínimos al 86%; políticas de desconexión, acoso y seguridad vial | G100: Análisis de puestos al 40% | H100: 80 | I100: 3.1
A101: P6-A3-M1 | B101: P6 | C101: P6-A3 | D101: Priorizada | E101: 100% de perfiles, funciones y roles actualizados | F101: Modelo por competencias; manual de funciones al 100% | G101: Socializar el manual y el modelo | H101: 90 | I101: 3.1
A102: P6-A3-M2 | B102: P6 | C102: P6-A3 | D102: Priorizada | E102: 100% de colaboradores con plan de carrera | F102: Ninguno | G102: Diseñar el plan de carrera | H102: 10 | I102: 3.1
A103: P6-A4-M1 | B103: P6 | C103: P6-A4 | D103: Priorizada | E103: Política de contratación actualizada | F103: Proceso de selección al 100%; onboarding; 7 de 8 superan el periodo de prueba | G103: Cerrar trimestre Q4 2026 | H103: 80 | I103: 3.1
A104: P6-A5-M1 | B104: P6 | C104: P6-A5 | D104: Priorizada | E104: Nivelación salarial del 100% | F104: Nivelación por roles (2025); 100% de cargos con estructura salarial (2026) | G104: Falta realizar estudio de mercado | H104: 80 | I104: 3.1
A105: P6-A6-M1 | B105: P6 | C105: P6-A6 | D105: Priorizada | E105: Análisis jurídico, fiscal y contable de viabilidad | F105: Avalúos 2021; concepto de revisaría fiscal; Diagnostico de las casas | G105: Modelo aprobado con analisis jurídico | H105: 40 | I105: 3.2
A106: P6-A6-M3 | B106: P6 | C106: P6-A6 | D106: No priorizada | E106: CINDE ejecutor del canon, con seguros | F106: Contratos de uso con 2 entidades en Sabaneta | G106: Falta implementar estrategia | H106: 30 | I106: 3.2
A107: P6-N-M1 | B107: P6 | C107: P6-N | D107: Fuera del plan | E107: 95% de nóminas y afiliaciones correctas (2026) | F107: 100% en el Q1; migración a Siesa SBS | G107: Reporte del Q2 y el Q3 | H107: 90 | I107: 3.1

Sheet Análisis
A1: Análisis del cierre del plan 2022-2026
A2: Todo se calcula con fórmulas a partir de las hojas Programas, Acciones y Metas. No edite esta hoja: cambie los datos en Metas y aquí se actualiza solo.
A4: 1. Avance y estado de las acciones por programa
A5: Programa | B5: Avance | C5: Pendiente | D5: Acciones del plan | E5: Cumplidas | F5: En curso | G5: Rezagadas | H5: Mixtas | J5: clave de orden
A6: =Programas!B2 -> P1 Investigación-desarrollo | B6: =Programas!F2/100 -> 0.57 | C6: =1-B6 -> 0.43 | D6: =COUNTIFS(Acciones!$B:$B,Programas!A2,Acciones!$F:$F,"No") -> 3 | E6: =COUNTIFS(Acciones!$B:$B,Programas!A2,Acciones!$F:$F,"No",Acciones!$D:$D,"Cumplido") -> 0 | F6: =COUNTIFS(Acciones!$B:$B,Programas!A2,Acciones!$F:$F,"No",Acciones!$D:$D,"En curso") -> 1 | G6: =COUNTIFS(Acciones!$B:$B,Programas!A2,Acciones!$F:$F,"No",Acciones!$D:$D,"Rezagado") -> 1 | H6: =COUNTIFS(Acciones!$B:$B,Programas!A2,Acciones!$F:$F,"No",Acciones!$D:$D,"Mixto") -> 1 | J6: =B6+ROW()/1000000 -> 0.570006
A7: =Programas!B3 -> P2 Formación | B7: =Programas!F3/100 -> 0.79 | C7: =1-B7 -> 0.21 | D7: =COUNTIFS(Acciones!$B:$B,Programas!A3,Acciones!$F:$F,"No") -> 3 | E7: =COUNTIFS(Acciones!$B:$B,Programas!A3,Acciones!$F:$F,"No",Acciones!$D:$D,"Cumplido") -> 0 | F7: =COUNTIFS(Acciones!$B:$B,Programas!A3,Acciones!$F:$F,"No",Acciones!$D:$D,"En curso") -> 2 | G7: =COUNTIFS(Acciones!$B:$B,Programas!A3,Acciones!$F:$F,"No",Acciones!$D:$D,"Rezagado") -> 0 | H7: =COUNTIFS(Acciones!$B:$B,Programas!A3,Acciones!$F:$F,"No",Acciones!$D:$D,"Mixto") -> 1 | J7: =B7+ROW()/1000000 -> 0.790007
A8: =Programas!B4 -> P3 Circulación del conocimiento | B8: =Programas!F4/100 -> 0.49 | C8: =1-B8 -> 0.51 | D8: =COUNTIFS(Acciones!$B:$B,Programas!A4,Acciones!$F:$F,"No") -> 4 | E8: =COUNTIFS(Acciones!$B:$B,Programas!A4,Acciones!$F:$F,"No",Acciones!$D:$D,"Cumplido") -> 0 | F8: =COUNTIFS(Acciones!$B:$B,Programas!A4,Acciones!$F:$F,"No",Acciones!$D:$D,"En curso") -> 3 | G8: =COUNTIFS(Acciones!$B:$B,Programas!A4,Acciones!$F:$F,"No",Acciones!$D:$D,"Rezagado") -> 0 | H8: =COUNTIFS(Acciones!$B:$B,Programas!A4,Acciones!$F:$F,"No",Acciones!$D:$D,"Mixto") -> 1 | J8: =B8+ROW()/1000000 -> 0.490008
A9: =Programas!B5 -> P4 Transformación digital | B9: =Programas!F5/100 -> 0.5 | C9: =1-B9 -> 0.5 | D9: =COUNTIFS(Acciones!$B:$B,Programas!A5,Acciones!$F:$F,"No") -> 6 | E9: =COUNTIFS(Acciones!$B:$B,Programas!A5,Acciones!$F:$F,"No",Acciones!$D:$D,"Cumplido") -> 0 | F9: =COUNTIFS(Acciones!$B:$B,Programas!A5,Acciones!$F:$F,"No",Acciones!$D:$D,"En curso") -> 2 | G9: =COUNTIFS(Acciones!$B:$B,Programas!A5,Acciones!$F:$F,"No",Acciones!$D:$D,"Rezagado") -> 3 | H9: =COUNTIFS(Acciones!$B:$B,Programas!A5,Acciones!$F:$F,"No",Acciones!$D:$D,"Mixto") -> 1 | J9: =B9+ROW()/1000000 -> 0.500009
A10: =Programas!B6 -> P5 Planeación y CEA | B10: =Programas!F6/100 -> 0.46 | C10: =1-B10 -> 0.54 | D10: =COUNTIFS(Acciones!$B:$B,Programas!A6,Acciones!$F:$F,"No") -> 7 | E10: =COUNTIFS(Acciones!$B:$B,Programas!A6,Acciones!$F:$F,"No",Acciones!$D:$D,"Cumplido") -> 0 | F10: =COUNTIFS(Acciones!$B:$B,Programas!A6,Acciones!$F:$F,"No",Acciones!$D:$D,"En curso") -> 4 | G10: =COUNTIFS(Acciones!$B:$B,Programas!A6,Acciones!$F:$F,"No",Acciones!$D:$D,"Rezagado") -> 2 | H10: =COUNTIFS(Acciones!$B:$B,Programas!A6,Acciones!$F:$F,"No",Acciones!$D:$D,"Mixto") -> 1 | J10: =B10+ROW()/1000000 -> 0.46001
A11: =Programas!B7 -> P6 Talento humano | B11: =Programas!F7/100 -> 0.68 | C11: =1-B11 -> 0.32 | D11: =COUNTIFS(Acciones!$B:$B,Programas!A7,Acciones!$F:$F,"No") -> 6 | E11: =COUNTIFS(Acciones!$B:$B,Programas!A7,Acciones!$F:$F,"No",Acciones!$D:$D,"Cumplido") -> 0 | F11: =COUNTIFS(Acciones!$B:$B,Programas!A7,Acciones!$F:$F,"No",Acciones!$D:$D,"En curso") -> 5 | G11: =COUNTIFS(Acciones!$B:$B,Programas!A7,Acciones!$F:$F,"No",Acciones!$D:$D,"Rezagado") -> 0 | H11: =COUNTIFS(Acciones!$B:$B,Programas!A7,Acciones!$F:$F,"No",Acciones!$D:$D,"Mixto") -> 1 | J11: =B11+ROW()/1000000 -> 0.680011
A12: Plan (P1 a P6) | B12: =ROUND(AVERAGE(Programas!F2:F7),0)/100 -> 0.58 | C12: =1-B12 -> 0.42 | D12: =SUM(D6:D11) -> 29 | E12: =SUM(E6:E11) -> 0 | F12: =SUM(F6:F11) -> 17 | G12: =SUM(G6:G11) -> 6 | H12: =SUM(H6:H11) -> 6
A14: 2. Ranking de programas: quién logró más
A15: Puesto | B15: Programa | C15: Avance | J15: clave de orden
A16: 1 | B16: =INDEX($A$6:$A$11,MATCH(J16,$J$6:$J$11,0)) -> P2 Formación | C16: =INDEX($B$6:$B$11,MATCH(J16,$J$6:$J$11,0)) -> 0.79 | J16: =LARGE($J$6:$J$11,A16) -> 0.790007
A17: 2 | B17: =INDEX($A$6:$A$11,MATCH(J17,$J$6:$J$11,0)) -> P6 Talento humano | C17: =INDEX($B$6:$B$11,MATCH(J17,$J$6:$J$11,0)) -> 0.68 | J17: =LARGE($J$6:$J$11,A17) -> 0.680011
A18: 3 | B18: =INDEX($A$6:$A$11,MATCH(J18,$J$6:$J$11,0)) -> P1 Investigación-desarrollo | C18: =INDEX($B$6:$B$11,MATCH(J18,$J$6:$J$11,0)) -> 0.57 | J18: =LARGE($J$6:$J$11,A18) -> 0.570006
A19: 4 | B19: =INDEX($A$6:$A$11,MATCH(J19,$J$6:$J$11,0)) -> P4 Transformación digital | C19: =INDEX($B$6:$B$11,MATCH(J19,$J$6:$J$11,0)) -> 0.5 | J19: =LARGE($J$6:$J$11,A19) -> 0.500009
A20: 5 | B20: =INDEX($A$6:$A$11,MATCH(J20,$J$6:$J$11,0)) -> P3 Circulación del conocimiento | C20: =INDEX($B$6:$B$11,MATCH(J20,$J$6:$J$11,0)) -> 0.49 | J20: =LARGE($J$6:$J$11,A20) -> 0.490008
A21: 6 | B21: =INDEX($A$6:$A$11,MATCH(J21,$J$6:$J$11,0)) -> P5 Planeación y CEA | C21: =INDEX($B$6:$B$11,MATCH(J21,$J$6:$J$11,0)) -> 0.46 | J21: =LARGE($J$6:$J$11,A21) -> 0.46001
A23: 3. Metas del plan por nivel de cumplimiento
A24: Programa | B24: Logradas (90% o más) | C24: Avance alto (70% a 89%) | D24: Avance medio (40% a 69%) | E24: Avance bajo (menos de 40%) | F24: Total de metas
A25: =Programas!B2 -> P1 Investigación-desarrollo | B25: =COUNTIFS(Metas!$B:$B,Programas!A2,Metas!$D:$D,"<>Fuera del plan",Metas!$H:$H,">=90") -> 4 | C25: =COUNTIFS(Metas!$B:$B,Programas!A2,Metas!$D:$D,"<>Fuera del plan",Metas!$H:$H,">=70",Metas!$H:$H,"<90") -> 1 | D25: =COUNTIFS(Metas!$B:$B,Programas!A2,Metas!$D:$D,"<>Fuera del plan",Metas!$H:$H,">=40",Metas!$H:$H,"<70") -> 6 | E25: =COUNTIFS(Metas!$B:$B,Programas!A2,Metas!$D:$D,"<>Fuera del plan",Metas!$H:$H,"<40") -> 4 | F25: =SUM(B25:E25) -> 15
A26: =Programas!B3 -> P2 Formación | B26: =COUNTIFS(Metas!$B:$B,Programas!A3,Metas!$D:$D,"<>Fuera del plan",Metas!$H:$H,">=90") -> 3 | C26: =COUNTIFS(Metas!$B:$B,Programas!A3,Metas!$D:$D,"<>Fuera del plan",Metas!$H:$H,">=70",Metas!$H:$H,"<90") -> 8 | D26: =COUNTIFS(Metas!$B:$B,Programas!A3,Metas!$D:$D,"<>Fuera del plan",Metas!$H:$H,">=40",Metas!$H:$H,"<70") -> 2 | E26: =COUNTIFS(Metas!$B:$B,Programas!A3,Metas!$D:$D,"<>Fuera del plan",Metas!$H:$H,"<40") -> 0 | F26: =SUM(B26:E26) -> 13
A27: =Programas!B4 -> P3 Circulación del conocimiento | B27: =COUNTIFS(Metas!$B:$B,Programas!A4,Metas!$D:$D,"<>Fuera del plan",Metas!$H:$H,">=90") -> 1 | C27: =COUNTIFS(Metas!$B:$B,Programas!A4,Metas!$D:$D,"<>Fuera del plan",Metas!$H:$H,">=70",Metas!$H:$H,"<90") -> 5 | D27: =COUNTIFS(Metas!$B:$B,Programas!A4,Metas!$D:$D,"<>Fuera del plan",Metas!$H:$H,">=40",Metas!$H:$H,"<70") -> 8 | E27: =COUNTIFS(Metas!$B:$B,Programas!A4,Metas!$D:$D,"<>Fuera del plan",Metas!$H:$H,"<40") -> 8 | F27: =SUM(B27:E27) -> 22
A28: =Programas!B5 -> P4 Transformación digital | B28: =COUNTIFS(Metas!$B:$B,Programas!A5,Metas!$D:$D,"<>Fuera del plan",Metas!$H:$H,">=90") -> 4 | C28: =COUNTIFS(Metas!$B:$B,Programas!A5,Metas!$D:$D,"<>Fuera del plan",Metas!$H:$H,">=70",Metas!$H:$H,"<90") -> 2 | D28: =COUNTIFS(Metas!$B:$B,Programas!A5,Metas!$D:$D,"<>Fuera del plan",Metas!$H:$H,">=40",Metas!$H:$H,"<70") -> 5 | E28: =COUNTIFS(Metas!$B:$B,Programas!A5,Metas!$D:$D,"<>Fuera del plan",Metas!$H:$H,"<40") -> 7 | F28: =SUM(B28:E28) -> 18
A29: =Programas!B6 -> P5 Planeación y CEA | B29: =COUNTIFS(Metas!$B:$B,Programas!A6,Metas!$D:$D,"<>Fuera del plan",Metas!$H:$H,">=90") -> 0 | C29: =COUNTIFS(Metas!$B:$B,Programas!A6,Metas!$D:$D,"<>Fuera del plan",Metas!$H:$H,">=70",Metas!$H:$H,"<90") -> 3 | D29: =COUNTIFS(Metas!$B:$B,Programas!A6,Metas!$D:$D,"<>Fuera del plan",Metas!$H:$H,">=40",Metas!$H:$H,"<70") -> 9 | E29: =COUNTIFS(Metas!$B:$B,Programas!A6,Metas!$D:$D,"<>Fuera del plan",Metas!$H:$H,"<40") -> 5 | F29: =SUM(B29:E29) -> 17
A30: =Programas!B7 -> P6 Talento humano | B30: =COUNTIFS(Metas!$B:$B,Programas!A7,Metas!$D:$D,"<>Fuera del plan",Metas!$H:$H,">=90") -> 5 | C30: =COUNTIFS(Metas!$B:$B,Programas!A7,Metas!$D:$D,"<>Fuera del plan",Metas!$H:$H,">=70",Metas!$H:$H,"<90") -> 4 | D30: =COUNTIFS(Metas!$B:$B,Programas!A7,Metas!$D:$D,"<>Fuera del plan",Metas!$H:$H,">=40",Metas!$H:$H,"<70") -> 1 | E30: =COUNTIFS(Metas!$B:$B,Programas!A7,Metas!$D:$D,"<>Fuera del plan",Metas!$H:$H,"<40") -> 3 | F30: =SUM(B30:E30) -> 13
A31: Plan (P1 a P6) | B31: =SUM(B25:B30) -> 17 | C31: =SUM(C25:C30) -> 23 | D31: =SUM(D25:D30) -> 31 | E31: =SUM(E25:E30) -> 27 | F31: =SUM(F25:F30) -> 98
A33: 4. Avance de las metas priorizadas frente a las no priorizadas
A34: Programa | B34: Metas priorizadas | C34: Metas no priorizadas
A35: =Programas!B2 -> P1 Investigación-desarrollo | B35: =IFERROR(AVERAGEIFS(Metas!$H:$H,Metas!$B:$B,Programas!A2,Metas!$D:$D,"Priorizada")/100,0) -> 0.65 | C35: =IFERROR(AVERAGEIFS(Metas!$H:$H,Metas!$B:$B,Programas!A2,Metas!$D:$D,"No priorizada")/100,0) -> 0.425
A36: =Programas!B3 -> P2 Formación | B36: =IFERROR(AVERAGEIFS(Metas!$H:$H,Metas!$B:$B,Programas!A3,Metas!$D:$D,"Priorizada")/100,0) -> 0.805 | C36: =IFERROR(AVERAGEIFS(Metas!$H:$H,Metas!$B:$B,Programas!A3,Metas!$D:$D,"No priorizada")/100,0) -> 0.7
A37: =Programas!B4 -> P3 Circulación del conocimiento | B37: =IFERROR(AVERAGEIFS(Metas!$H:$H,Metas!$B:$B,Programas!A4,Metas!$D:$D,"Priorizada")/100,0) -> 0.50238095 | C37: =IFERROR(AVERAGEIFS(Metas!$H:$H,Metas!$B:$B,Programas!A4,Metas!$D:$D,"No priorizada")/100,0) -> 0.25
A38: =Programas!B5 -> P4 Transformación digital | B38: =IFERROR(AVERAGEIFS(Metas!$H:$H,Metas!$B:$B,Programas!A5,Metas!$D:$D,"Priorizada")/100,0) -> 0.57769231 | C38: =IFERROR(AVERAGEIFS(Metas!$H:$H,Metas!$B:$B,Programas!A5,Metas!$D:$D,"No priorizada")/100,0) -> 0.26
A39: =Programas!B6 -> P5 Planeación y CEA | B39: =IFERROR(AVERAGEIFS(Metas!$H:$H,Metas!$B:$B,Programas!A6,Metas!$D:$D,"Priorizada")/100,0) -> 0.625 | C39: =IFERROR(AVERAGEIFS(Metas!$H:$H,Metas!$B:$B,Programas!A6,Metas!$D:$D,"No priorizada")/100,0) -> 0.34545455
A40: =Programas!B7 -> P6 Talento humano | B40: =IFERROR(AVERAGEIFS(Metas!$H:$H,Metas!$B:$B,Programas!A7,Metas!$D:$D,"Priorizada")/100,0) -> 0.72083333 | C40: =IFERROR(AVERAGEIFS(Metas!$H:$H,Metas!$B:$B,Programas!A7,Metas!$D:$D,"No priorizada")/100,0) -> 0.3
A41: Plan (P1 a P6) | B41: =IFERROR(AVERAGEIFS(Metas!$H:$H,Metas!$D:$D,"Priorizada")/100,0) -> 0.62547945 | C41: =IFERROR(AVERAGEIFS(Metas!$H:$H,Metas!$D:$D,"No priorizada")/100,0) -> 0.378
A42: Promedio simple del porcentaje de las metas de cada tipo. Un 0% indica que el programa no tiene metas de ese tipo.
A44: 5. Avance por acción del plan, de mayor a menor
A45: Puesto | B45: Acción | C45: Avance | D45: Estado | K45: clave | L45: Acciones (apoyo) | M45: clave
...

Sheet Minciencias
A1: categoria_id | B1: dimension | C1: criterio | D1: que_evalua | E1: orden
A2: 1.1 | B2: 1. Estrategia | C2: 1.1 Misión | D2: Alineación de la misión con el objeto social y con las actividades de I+D. Se responde con la misión vigente; ninguna meta del plan la mide. | E2: 1
A3: 1.2 | B3: 1. Estrategia | C3: 1.2 Planificación estratégica | D3: Plan con objetivos y metas medibles, cuadro de mando, revisión anual, apropiación del plan y procedimientos documentados. | E3: 2
A4: 2.1 | B4: 2. Interrelación | C4: 2.1 Relaciones con el medio | D4: Convenios con actores del SNCTI, proyectos conjuntos, estrategia de nuevas alianzas y número de alianzas al año. | E4: 3
A5: 3.1 | B5: 3. Recursos | C5: 3.1 Recurso humano | D5: Personal científico, formación, reconocimiento como investigadores, vinculación documentada y formación continua. | E5: 4
A6: 3.2 | B6: 3. Recursos | C6: 3.2 Recurso financiero | D6: Presupuesto por fases, recursos externos para I+D y captación de recursos públicos y privados. | E6: 5
A7: 3.3 | B7: 3. Recursos | C7: 3.3 Infraestructura | D7: Equipos, inversión en tecnologías de la información, plan tecnológico, software y bases de datos adecuados. | E7: 6
A8: 4.1-NC | B8: 4. Resultados | C8: 4.1 Productos y proyectos de I+D: nuevo conocimiento y desarrollo | D8: Productos de nuevo conocimiento, proyectos de I+D, continuidad de las líneas y resultados conjuntos con otros actores. | E8: 7
A9: 4.1-ASC | B9: 4. Resultados | C9: 4.1 Productos y proyectos de I+D: apropiación social del conocimiento | D9: Productos de apropiación social, divulgación de resultados y participación de comunidades y actores. | E9: 8
A10: 4.1-FRH | B10: 4. Resultados | C10: 4.1 Productos y proyectos de I+D: formación de investigadores | D10: Formación de investigadores para CTeI: programas de formación avanzada, semilleros y jóvenes investigadores. | E10: 9

Sheet Logros_adicionales
A1: logro_id | B1: categoria_minciencias | C1: programa_id | D1: anio | E1: logro | F1: fuente
A2: L01 | B2: 3.1 | C2: P1 | D2: 2023 | E2: Reconocimiento a la investigadora Johanna Patiño en la convocatoria 635 Orquídeas de Minciencias: 1.er puesto en Caldas y 3.er puesto nacional | F2: I23 p. 4
A3: L02 | B3: 3.1 | C3: P1 | D3: 2024 | E3: Dos de cuatro propuestas seleccionadas en la convocatoria 948 Orquídeas: Mujeres en la Ciencia | F3: I24 d. 8
A4: L03 | B4: 3.1 | C4: P6 | D4: 2023 | E4: Planta de 76 colaboradores en nómina y 111 personas en todas las modalidades de contrato | F4: I23 p. 22
A5: L04 | B5: 3.2 | C5: P5 | D5: 2023 | E5: Presupuesto de ingresos de $9.328 millones, con 75% facturado a octubre ($7.032 millones) y ejecución presupuestal a mes vencido | F5: I23 pp. 24-25
A6: L05 | B6: 3.2 | C6: P5 | D6: 2023 | E6: Seguimiento financiero al 85% de los 30 programas y 99% de las obligaciones tributarias cumplidas a tiempo | F6: I23 p. 25
A7: L06 | B7: 4.1-NC | C7: P1 | D7: 2023 | E7: Publicaciones con resultados de proyectos en revistas indexadas: Academia de Ciencias de Nueva York (A1), RLCSNJ (B), Aletheia (B), Revista de Ciencias Sociales de la U. de Costa Rica (B) e Interdisciplinaria | F7: I23 p. 4
A8: L07 | B8: 4.1-ASC | C8: P1 | D8: 2023 | E8: Participación en eventos académicos nacionales e internacionales: V Bienal LAyC, Bienal internacional de educación y cultura de paz, pasantías de Escuela Activa Urbana en Chile y España, y congresos en España y Grecia | F8: I23 p. 5
A9: L08 | B9: 4.1-ASC | C9: P3 | D9: 2024 | E9: Participación en 87 eventos nacionales e internacionales | F9: I24 d. 15
A10: L09 | B10: 4.1-ASC | C10: P3 | D10: 2023 | E10: Nuevo sitio web con 14.107 visitas orgánicas de cerca de 60 países; 55 emisiones en YouTube con 7.041 reproducciones | F10: I23 pp. 9-10
A11: L10 | B11: 4.1-ASC | C11: P3 | D11: 2024 | E11: 40.849 visitas al sitio web y 308.000 interacciones en los canales de divulgación | F11: I24 d. 15
A12: L11 | B12: 4.1-ASC | C12: P3 | D12: 2023 | E12: 845 personas recibieron publicaciones de CINDE y la UMZ en lanzamientos y eventos | F12: I23 p. 11
A13: L12 | B13: 4.1-FRH | C13: P2 | D13: 2023 | E13: Maestría en Primera Infancia: 6 graduados de la cohorte 1; sus estudiantes ganaron el premio a experiencias inspiradoras y viajaron a Finlandia y Reggio Emilia | F13: I23 p. 7
A14: L13 | B14: 4.1-FRH | C14: P2 | D14: 2024 | E14: 357 estudiantes matriculados, 117 graduados y 11 cohortes activas en formación avanzada | F14: I24 d. 12

Sheet Preguntas_formato
A1: pregunta_id | B1: criterio | C1: pregunta | D1: respuesta | E1: evidencia | F1: metas_relacionadas | G1: responsable | H1: respuesta_area
A2: 1.1-1 | B2: 1.1 | C2: ¿La misión se alinea con el objeto social? | D2: Sin evidencia | E2: No revisamos los estatutos ni el objeto social registrado, así que no hay con qué compararla. | G2: Dirección
A3: 1.1-2 | B3: 1.1 | C3: ¿Existe coherencia entre la misión y las actividades de I+D? | D3: Sí | E3: Las actividades de I+D se centran en niñez y juventud, como la misión: 4 grupos de investigación (3 en A1 o A), 6 líneas activas y proyectos con comunidades como Expedición Pacífica y Territorios del Buen Vivir. | F3: P1-A1-M1, P1-A1-M2, P1-A2-M3
A4: 1.2-1 | B4: 1.2 | C4: ¿Existe un plan estratégico para incorporar nuevos conocimientos, nuevas tecnologías, al desarrollo de nuevos productos o servicios? | D4: Sí | E4: El plan estratégico 2022-2026 tiene 7 programas, entre ellos Transformación digital (P4) y la co-creación de oferta propia (P1-A2). | F4: P4-A1 a P4-A6, P1-A2
A5: 1.2-2 | B5: 1.2 | C5: ¿Los objetivos son claramente definidos y viables? | D5: Sí | E5: Los objetivos están definidos en 29 acciones y 98 metas. La viabilidad fue parcial: el plan cierra en 58% y 17 de 98 metas están logradas. | F5: Todo el plan
A6: 1.2-3 | B6: 1.2 | C6: ¿Se cuenta con un cuadro de mando integral que permita hacer seguimiento a la implementación de las estrategias y objetivos de I+D+i definidos? | D6: Sí | E6: Las planeaciones 2025 y 2026 tienen indicadores con seguimiento trimestral, y en 2026 se construyó el sistema de indicadores institucional. | F6: P5-N-M2, P5-A1
A7: 1.2-4 | B7: 1.2 | C7: ¿Existe una estrategia definida para afrontar los retos de I+D? | D7: Sí | E7: El Programa 1 del plan define tres acciones para I+D (grupos y líneas, co-creación de proyectos y nuevas generaciones), priorizadas en 2025 y 2026. | F7: P1-A1, P1-A2, P1-A3
A8: 1.2-5 | B8: 1.2 | C8: ¿Cada año se revisa y actualiza el plan estratégico definido? | D8: No | E8: Solo hubo planeación anual con indicadores en 2025 y 2026. De 2022 a 2024 hubo informes de avance, pero no una revisión anual documentada del plan. | F8: P5-N-M2
A9: 1.2-6 | B9: 1.2 | C9: ¿Existen metas medibles y verificables de manera objetiva para cada indicador? | D9: No | E9: Varias metas del plan no son medibles (por ejemplo, 'mayor alcance y reconocimiento internacional'). Los indicadores 2025-2026 sí tienen meta, aunque varios suman avances trimestrales en lugar de medir. | F9: P4-A6-M3, P3-A4-M1
A10: 1.2-7 | B10: 1.2 | C10: ¿Existe un nivel de apropiación del plan estratégico al interior de la organización? | D10: Sin evidencia | E10: Hay evidencia de apropiación de la nueva estructura (97% de aprobación en 2024), pero no una medición de apropiación del plan estratégico. | F10: P5-A5-M2 | G10: Planeación
A11: 1.2-8 | B11: 1.2 | C11: ¿La dirección ejecutiva estructura el proceso de innovación en diversas etapas claves e incentiva la participación de las diferentes áreas del centro? | D11: Sí | E11: El proceso de innovación se configuró en 2022 dentro del campo de circulación; hubo un encuentro nacional con 4 macroproyectos co-diseñados (2022) y un colaboratorio de investigadores (2025). | F11: P1-A2-M2
A12: 1.2-9 | B12: 1.2 | C12: ¿La alta gerencia se preocupa por la asignación de recursos y por el seguimiento a la ejecución de las actividades de I+D? | D12: Sí | E12: Proyectos del SGR con 100 puntos en GESPROY y primer lugar en desempeño (2023); seguimiento semestral a 8 proyectos (2025); seguimiento financiero al 85% de los 30 programas (2023). | F12: P1-A2-M1
A13: 1.2-10 | B13: 1.2 | C13: ¿La alta gerencia es dispuesta a asumir riesgos y asignar incentivos para las buenas ideas de los empleados? | D13: Sin evidencia | E13: La política de incentivos está en borrador (90%) y se refiere a becas y beneficios, no a incentivos por ideas. No hay evidencia sobre asunción de riesgos. | F13: P6-A1-M3 | G13: Dirección
A14: 1.2-11 | B14: 1.2 | C14: ¿El centro cuenta con procedimientos documentados y apropiados por los empleados para la gestión del sistema de investigación y gestión de proyectos de I+D? | D14: Sí | E14: Lineamientos nacionales de I+D (2022), registro estandarizado en SharePoint del campo de I+D (2023) y lineamientos de calidad finalizados (2025). Su apropiación es parcial: el 50% de los procesos está documentado y los lineamientos no se aprobaron. | F14: P4-A1-M3, P5-A1-M1
A15: 2.1-1 | B15: 2.1 | C15: ¿Cuenta con acuerdos o convenios de cooperación con otros actores del SNCTI? | D15: Sí | E15: Convenios con la U. de Manizales (CEANJ), la U. Luis Amigó y la F. CORPAS, y 8 convenios internacionales activos en 2024 (CLACSO, PUC São Paulo, El COLEF, entre otros). | F15: P5-A2-M1, P5-A4-M1
A16: 2.1-2 | B16: 2.1 | C16: ¿Existe coherencia entre la misión y las actividades de I+D? | D16: Sí | E16: Igual que en 1.1: las alianzas y proyectos se centran en niñez y juventud. | F16: P1-A1
A17: 2.1-3 | B17: 2.1 | C17: ¿El Centro contempla procesos que le ayudan a fortalecer sus capacidades, reforzar vínculos y desarrollar actividades misionales en colaboración con actores clave nacionales e internacionales? | D17: Sí | E17: Participación en 29 redes (2025) y agenda de internacionalización con 23 actores con acercamiento en 2026. | F17: P3-A4-M1, P3-A4-M7
A18: 2.1-4 | B18: 2.1 | C18: ¿Existe ejecución de proyectos realizados con otros actores del SNCTeI? | D18: Sí | E18: Proyecto de regalías de gobernanza en CTeI con la UMZ, la U. Autónoma de Manizales, la U. de Caldas y otras entidades; Territorios del Cuidado con la UMZ y CLACSO. | F18: P5-A3-M2, P1-A2-M3
A19: 2.1-5 | B19: 2.1 | C19: ¿Se ha hecho uso de estas alianzas para el fortalecimiento del centro? | D19: Sí | E19: La alianza con la UMZ sostiene el CEANJ, cofinanció jóvenes investigadores y permitió coediciones (CLACSO y UMZ, 2026). | F19: P5-A3, P3-A3-M4
A20: 2.1-6 | B20: 2.1 | C20: ¿Cuentan con estrategias para la conformación de nuevas alianzas? | D20: Sí | E20: Agenda de internacionalización 2026 con propuestas a Horizonte Europa, La Caixa y Erasmus+, y convenios en curso con la UNAD y la U. Luis Amigó. | F20: P5-A2-M1, P3-A4-M2
A21: 2.1-7 | B21: 2.1 | C21: ¿Es la interrelación con otros actores, un factor de importancia para la ejecución de proyectos? | D21: Sí | E21: La mayoría de los proyectos se ejecutan en alianza (SGR, CLACSO, UMZ, Botnar, PIASE). | F21: P1-A2-M3
A22: 2.1-8 | B22: 2.1 | C22: ¿Cuántas alianzas o convenios de cooperación se realizan al año? | D22: Sin evidencia | E22: No hay un conteo anual. Datos parciales: 9 proyectos nacionales y 3 internacionales en 2023, y 8 convenios internacionales activos en 2024. | F22: P5-A2 | G22: Gestión estratégica
A23: 2.1-9 | B23: 2.1 | C23: ¿El centro cuenta con suficiente interrelación para el desarrollo de sus actividades? | D23: Sí | E23: Red amplia de aliados nacionales e internacionales, aunque las metas de alianzas de la Escuela Digital no se cumplieron. | F23: P3-A4, P4-A6
A24: 3.1-1 | B24: 3.1 | C24: ¿Existe personal científico, técnico o administrativo? | D24: Sí | E24: 76 colaboradores en nómina y 111 personas en todas las modalidades de contrato (2023). | F24: Logro L03
A25: 3.1-2 | B25: 3.1 | C25: ¿El personal científico cuenta con la formación académica requerida para el desarrollo de actividades de investigación? | D25: Sin evidencia | E25: Las fuentes del plan no tienen datos sobre la formación del personal científico. | G25: Talento Humano e I+D
A26: 3.1-3 | B26: 3.1 | C26: ¿Más del 70% del personal científico cuenta con reconocimiento vigente como investigador? | D26: Sin evidencia | E26: Las fuentes del plan no tienen datos sobre el reconocimiento de los investigadores. | G26: Talento Humano e I+D
A27: 3.1-4 | B27: 3.1 | C27: ¿Más del 60% del personal científico cuenta con formación de doctorado? | D27: Sin evidencia | E27: Las fuentes del plan no tienen datos sobre doctores en el personal científico. | G27: Talento Humano e I+D
A28: 3.1-5 | B28: 3.1 | C28: ¿El personal científico sin reconocimiento cuenta con hoja de vida registrada en CvLAC? | D28: No | E28: En 2023 se llegó al 80% de la información de los investigadores en CvLAC; no todos la tienen completa. | F28: P1-A1
A29: 3.1-6 | B29: 3.1 | C29: ¿El personal científico relacionado es suficiente para la realización de las actividades de I+D? | D29: Sin evidencia | E29: Las fuentes del plan no tienen un análisis de suficiencia del personal científico. | G29: I+D
A30: 3.1-7 | B30: 3.1 | C30: ¿Más del 50% del personal científico cuenta con vinculación de tiempo completo? | D30: Sin evidencia | E30: Las fuentes del plan no tienen datos sobre el tipo de dedicación del personal científico. | G30: Talento Humano
A31: 3.1-8 | B31: 3.1 | C31: ¿Existen documentos que soporten el tipo de vinculación de cada integrante del centro, detallando sus funciones y horas de dedicación? | D31: Sí | E31: Manual de roles y funciones con fichas por cargo (90%), matriz de capacidad y asignación laboral (2023) y matriz de contratos (50%). | F31: P6-A3-M1, P6-A4-M1
A32: 3.1-9 | B32: 3.1 | C32: ¿El número de investigadores o personal científico se incrementa anualmente? | D32: Sin evidencia | E32: Las fuentes del plan no tienen el número de investigadores por año. | G32: Talento Humano e I+D
A33: 3.1-10 | B33: 3.1 | C33: ¿El personal de apoyo cuenta con registro en CvLAC? | D33: Sin evidencia | E33: Las fuentes del plan no tienen datos sobre el registro del personal de apoyo. | G33: I+D
A34: 3.1-11 | B34: 3.1 | C34: ¿Existen estrategias de formación continua para el personal científico, técnico y administrativo? | D34: Sí | E34: Formación de 20 líderes en Microsoft 365 (2023), capacitación en estilos de mando (2025), plan de formación en nuevas tecnologías al 70% y evaluación de desempeño al 95% del personal (2026). | F34: P4-A1-M4, P6-A3-M1
A35: 3.2-1 | B35: 3.2 | C35: ¿Existe una planificación temporal detallada, y un presupuesto asignado con metas a conseguir para cada fase y con una relación de costes previstos? | D35: Sí | E35: Presupuesto anual por programas y proyectos, con ejecución a mes vencido (2023). No hay evidencia de presupuesto por fases de cada proyecto. | F35: Logro L04
A36: 3.2-2 | B36: 3.2 | C36: ¿Se reciben recursos de fuentes externas para financiar los proyectos de I+D? | D36: Sí | E36: Proyectos del Sistema General de Regalías, CLACSO, Botnar, PIASE y Minciencias. | F36: P5-A2-M2, P5-A3-M2
A37: 3.2-3 | B37: 3.2 | C37: ¿El centro cuenta con un rubro para imprevistos o asignación esporádica de recursos, para financiar la selección de nuevas ideas y su implementación a través de la ejecución de proyectos de I+D? | D37: Sin evidencia | E37: Las fuentes del plan no mencionan un rubro para imprevistos o para nuevas ideas. | G37: Gestión financiera
A38: 3.2-4 | B38: 3.2 | C38: ¿Los recursos financieros son suficientes para llevar a cabo las diferentes actividades de acuerdo con las líneas de acción priorizadas en el marco de la estrategia de I+D? | D38: No | E38: La Escuela Digital Ékora se suspendió por falta de recursos (2025) y las propuestas de oferta propia de 2026 no tienen financiación. La composición de ingresos quedó lejos de la meta. | F38: P4-A3-M1, P1-A2-M3, P5-A7
A39: 3.2-5 | B39: 3.2 | C39: ¿El Centro gestiona la captación de recursos financieros (sector público, sector privado, acceso a convocatorias para proyectos de investigación internas, externas, entre otros)? | D39: Sí | E39: 32 propuestas presentadas en 2023, 19 en 2024 y 24% de aprobación de convocatorias en 2026 (meta 20%). | F39: P5-A2-M2
A40: 3.3-1 | B40: 3.3 | C40: ¿El centro cuenta con maquinaria y laboratorios de uso exclusivo para la ejecución de las actividades de I+D? | D40: Sin evidencia | E40: Las fuentes del plan no mencionan laboratorios ni equipos de uso exclusivo para I+D. | G40: Tecnología y Administrativa
...
